2024-08-05 09:12:27,661 - Training the Model script not found: JarvisPhone/training/train.py
2024-08-05 09:12:27,661 - Making Predictions script not found: JarvisPhone/predictions.py
2024-08-05 09:12:27,661 - Continuous Learning script not found: JarvisPhone/web_content/continuous_learning.py
2024-08-05 09:12:27,669 - All tasks completed successfully!
2024-08-05 09:14:36,563 - Training the Model script not found: JarvisPhone/training/train.py
2024-08-05 09:14:36,563 - Making Predictions script not found: JarvisPhone/predictions.py
2024-08-05 09:14:36,563 - Continuous Learning script not found: JarvisPhone/web_content/continuous_learning.py
2024-08-05 09:14:36,563 - All tasks completed successfully!
2024-08-05 09:25:25,841 - Training the Model script not found: TEST\JarvisPhone	raining	rain.py
2024-08-05 09:25:25,841 - Making Predictions script not found: JarvisPhone/predictions.py
2024-08-05 09:25:25,841 - Continuous Learning script not found: JarvisPhone/web_content/continuous_learning.py
2024-08-05 09:25:25,841 - All tasks completed successfully!
2024-08-05 09:26:35,922 - Executing Training the Model...
2024-08-05 09:26:35,922 - Executing Making Predictions...
2024-08-05 09:26:35,922 - Executing Continuous Learning...
2024-08-05 09:26:43,595 - Error executing Training the Model: Traceback (most recent call last):
  File "C:\Users\proalafalda\AppData\Local\Programs\Python\Python312\Lib\site-packages\tensorflow\python\pywrap_tensorflow.py", line 70, in <module>
    from tensorflow.python._pywrap_tensorflow_internal import *
ImportError: DLL load failed while importing _pywrap_tensorflow_internal: Error en una rutina de inicialización de biblioteca de vínculos dinámicos (DLL).

During handling of the above exception, another exception occurred:

Traceback (most recent call last):
  File "C:\Users\proalafalda\Documents\GHUBJordan\ProBestoJarvisAI\TEST\JarvisPhone\training\train.py", line 2, in <module>
    import tensorflow as tf
  File "C:\Users\proalafalda\AppData\Local\Programs\Python\Python312\Lib\site-packages\tensorflow\__init__.py", line 38, in <module>
    from tensorflow.python import pywrap_tensorflow as _pywrap_tensorflow  # pylint: disable=unused-import
    ^^^^^^^^^^^^^^^^^^^^^^^^^^^^^^^^^^^^^^^^^^^^^^^^^^^^^^^^^^^^^^^^^^^^^
  File "C:\Users\proalafalda\AppData\Local\Programs\Python\Python312\Lib\site-packages\tensorflow\python\pywrap_tensorflow.py", line 85, in <module>
    raise ImportError(
ImportError: Traceback (most recent call last):
  File "C:\Users\proalafalda\AppData\Local\Programs\Python\Python312\Lib\site-packages\tensorflow\python\pywrap_tensorflow.py", line 70, in <module>
    from tensorflow.python._pywrap_tensorflow_internal import *
ImportError: DLL load failed while importing _pywrap_tensorflow_internal: Error en una rutina de inicialización de biblioteca de vínculos dinámicos (DLL).


Failed to load the native TensorFlow runtime.
See https://www.tensorflow.org/install/errors for some common causes and solutions.
If you need help, create an issue at https://github.com/tensorflow/tensorflow/issues and include the entire stack trace above this error message.

2024-08-05 09:26:43,595 - Error executing Making Predictions: Traceback (most recent call last):
  File "C:\Users\proalafalda\AppData\Local\Programs\Python\Python312\Lib\site-packages\tensorflow\python\pywrap_tensorflow.py", line 70, in <module>
    from tensorflow.python._pywrap_tensorflow_internal import *
ImportError: DLL load failed while importing _pywrap_tensorflow_internal: Error en una rutina de inicialización de biblioteca de vínculos dinámicos (DLL).

During handling of the above exception, another exception occurred:

Traceback (most recent call last):
  File "C:\Users\proalafalda\Documents\GHUBJordan\ProBestoJarvisAI\TEST\JarvisPhone\predictions.py", line 3, in <module>
    import tensorflow as tf
  File "C:\Users\proalafalda\AppData\Local\Programs\Python\Python312\Lib\site-packages\tensorflow\__init__.py", line 38, in <module>
    from tensorflow.python import pywrap_tensorflow as _pywrap_tensorflow  # pylint: disable=unused-import
    ^^^^^^^^^^^^^^^^^^^^^^^^^^^^^^^^^^^^^^^^^^^^^^^^^^^^^^^^^^^^^^^^^^^^^
  File "C:\Users\proalafalda\AppData\Local\Programs\Python\Python312\Lib\site-packages\tensorflow\python\pywrap_tensorflow.py", line 85, in <module>
    raise ImportError(
ImportError: Traceback (most recent call last):
  File "C:\Users\proalafalda\AppData\Local\Programs\Python\Python312\Lib\site-packages\tensorflow\python\pywrap_tensorflow.py", line 70, in <module>
    from tensorflow.python._pywrap_tensorflow_internal import *
ImportError: DLL load failed while importing _pywrap_tensorflow_internal: Error en una rutina de inicialización de biblioteca de vínculos dinámicos (DLL).


Failed to load the native TensorFlow runtime.
See https://www.tensorflow.org/install/errors for some common causes and solutions.
If you need help, create an issue at https://github.com/tensorflow/tensorflow/issues and include the entire stack trace above this error message.

2024-08-12 08:40:17,139 - Executing Training the Model...
2024-08-12 08:40:17,194 - Executing Making Predictions...
2024-08-12 08:40:17,270 - Executing Continuous Learning...
2024-08-12 08:40:26,868 - Error executing Making Predictions: Traceback (most recent call last):
  File "C:\Users\proalafalda\AppData\Local\Programs\Python\Python312\Lib\site-packages\tensorflow\python\pywrap_tensorflow.py", line 70, in <module>
    from tensorflow.python._pywrap_tensorflow_internal import *
ImportError: DLL load failed while importing _pywrap_tensorflow_internal: Error en una rutina de inicialización de biblioteca de vínculos dinámicos (DLL).

During handling of the above exception, another exception occurred:

Traceback (most recent call last):
  File "C:\Users\proalafalda\Documents\GHUBJordan\ProBestoJarvisAI\TEST\JarvisPhone\predictions.py", line 3, in <module>
    import tensorflow as tf
  File "C:\Users\proalafalda\AppData\Local\Programs\Python\Python312\Lib\site-packages\tensorflow\__init__.py", line 38, in <module>
    from tensorflow.python import pywrap_tensorflow as _pywrap_tensorflow  # pylint: disable=unused-import
    ^^^^^^^^^^^^^^^^^^^^^^^^^^^^^^^^^^^^^^^^^^^^^^^^^^^^^^^^^^^^^^^^^^^^^
  File "C:\Users\proalafalda\AppData\Local\Programs\Python\Python312\Lib\site-packages\tensorflow\python\pywrap_tensorflow.py", line 85, in <module>
    raise ImportError(
ImportError: Traceback (most recent call last):
  File "C:\Users\proalafalda\AppData\Local\Programs\Python\Python312\Lib\site-packages\tensorflow\python\pywrap_tensorflow.py", line 70, in <module>
    from tensorflow.python._pywrap_tensorflow_internal import *
ImportError: DLL load failed while importing _pywrap_tensorflow_internal: Error en una rutina de inicialización de biblioteca de vínculos dinámicos (DLL).


Failed to load the native TensorFlow runtime.
See https://www.tensorflow.org/install/errors for some common causes and solutions.
If you need help, create an issue at https://github.com/tensorflow/tensorflow/issues and include the entire stack trace above this error message.

2024-08-12 08:40:26,868 - Error executing Training the Model: Traceback (most recent call last):
  File "C:\Users\proalafalda\AppData\Local\Programs\Python\Python312\Lib\site-packages\tensorflow\python\pywrap_tensorflow.py", line 70, in <module>
    from tensorflow.python._pywrap_tensorflow_internal import *
ImportError: DLL load failed while importing _pywrap_tensorflow_internal: Error en una rutina de inicialización de biblioteca de vínculos dinámicos (DLL).

During handling of the above exception, another exception occurred:

Traceback (most recent call last):
  File "C:\Users\proalafalda\Documents\GHUBJordan\ProBestoJarvisAI\TEST\JarvisPhone\training\train.py", line 2, in <module>
    import tensorflow as tf
  File "C:\Users\proalafalda\AppData\Local\Programs\Python\Python312\Lib\site-packages\tensorflow\__init__.py", line 38, in <module>
    from tensorflow.python import pywrap_tensorflow as _pywrap_tensorflow  # pylint: disable=unused-import
    ^^^^^^^^^^^^^^^^^^^^^^^^^^^^^^^^^^^^^^^^^^^^^^^^^^^^^^^^^^^^^^^^^^^^^
  File "C:\Users\proalafalda\AppData\Local\Programs\Python\Python312\Lib\site-packages\tensorflow\python\pywrap_tensorflow.py", line 85, in <module>
    raise ImportError(
ImportError: Traceback (most recent call last):
  File "C:\Users\proalafalda\AppData\Local\Programs\Python\Python312\Lib\site-packages\tensorflow\python\pywrap_tensorflow.py", line 70, in <module>
    from tensorflow.python._pywrap_tensorflow_internal import *
ImportError: DLL load failed while importing _pywrap_tensorflow_internal: Error en una rutina de inicialización de biblioteca de vínculos dinámicos (DLL).


Failed to load the native TensorFlow runtime.
See https://www.tensorflow.org/install/errors for some common causes and solutions.
If you need help, create an issue at https://github.com/tensorflow/tensorflow/issues and include the entire stack trace above this error message.

2024-08-12 09:40:36,264 - 
2024-08-12 09:40:36,280 - All tasks completed successfully!
2024-08-12 09:46:47,941 - Executing Training the Model...
2024-08-12 09:46:47,941 - Executing Making Predictions...
2024-08-12 09:46:47,941 - Executing Continuous Learning...
2024-08-12 09:46:55,807 - Error executing Making Predictions: Traceback (most recent call last):
  File "C:\Users\proalafalda\AppData\Local\Programs\Python\Python312\Lib\site-packages\tensorflow\python\pywrap_tensorflow.py", line 70, in <module>
    from tensorflow.python._pywrap_tensorflow_internal import *
ImportError: DLL load failed while importing _pywrap_tensorflow_internal: Error en una rutina de inicialización de biblioteca de vínculos dinámicos (DLL).

During handling of the above exception, another exception occurred:

Traceback (most recent call last):
  File "C:\Users\proalafalda\Documents\GHUBJordan\ProBestoJarvisAI\TEST\JarvisPhone\predictions.py", line 3, in <module>
    import tensorflow as tf
  File "C:\Users\proalafalda\AppData\Local\Programs\Python\Python312\Lib\site-packages\tensorflow\__init__.py", line 38, in <module>
    from tensorflow.python import pywrap_tensorflow as _pywrap_tensorflow  # pylint: disable=unused-import
    ^^^^^^^^^^^^^^^^^^^^^^^^^^^^^^^^^^^^^^^^^^^^^^^^^^^^^^^^^^^^^^^^^^^^^
  File "C:\Users\proalafalda\AppData\Local\Programs\Python\Python312\Lib\site-packages\tensorflow\python\pywrap_tensorflow.py", line 85, in <module>
    raise ImportError(
ImportError: Traceback (most recent call last):
  File "C:\Users\proalafalda\AppData\Local\Programs\Python\Python312\Lib\site-packages\tensorflow\python\pywrap_tensorflow.py", line 70, in <module>
    from tensorflow.python._pywrap_tensorflow_internal import *
ImportError: DLL load failed while importing _pywrap_tensorflow_internal: Error en una rutina de inicialización de biblioteca de vínculos dinámicos (DLL).


Failed to load the native TensorFlow runtime.
See https://www.tensorflow.org/install/errors for some common causes and solutions.
If you need help, create an issue at https://github.com/tensorflow/tensorflow/issues and include the entire stack trace above this error message.

2024-08-12 09:46:57,374 - Error executing Training the Model: Traceback (most recent call last):
  File "C:\Users\proalafalda\AppData\Local\Programs\Python\Python312\Lib\site-packages\tensorflow\python\pywrap_tensorflow.py", line 70, in <module>
    from tensorflow.python._pywrap_tensorflow_internal import *
ImportError: DLL load failed while importing _pywrap_tensorflow_internal: Error en una rutina de inicialización de biblioteca de vínculos dinámicos (DLL).

During handling of the above exception, another exception occurred:

Traceback (most recent call last):
  File "C:\Users\proalafalda\Documents\GHUBJordan\ProBestoJarvisAI\TEST\JarvisPhone\training\train.py", line 2, in <module>
    import tensorflow as tf
  File "C:\Users\proalafalda\AppData\Local\Programs\Python\Python312\Lib\site-packages\tensorflow\__init__.py", line 38, in <module>
    from tensorflow.python import pywrap_tensorflow as _pywrap_tensorflow  # pylint: disable=unused-import
    ^^^^^^^^^^^^^^^^^^^^^^^^^^^^^^^^^^^^^^^^^^^^^^^^^^^^^^^^^^^^^^^^^^^^^
  File "C:\Users\proalafalda\AppData\Local\Programs\Python\Python312\Lib\site-packages\tensorflow\python\pywrap_tensorflow.py", line 85, in <module>
    raise ImportError(
ImportError: Traceback (most recent call last):
  File "C:\Users\proalafalda\AppData\Local\Programs\Python\Python312\Lib\site-packages\tensorflow\python\pywrap_tensorflow.py", line 70, in <module>
    from tensorflow.python._pywrap_tensorflow_internal import *
ImportError: DLL load failed while importing _pywrap_tensorflow_internal: Error en una rutina de inicialización de biblioteca de vínculos dinámicos (DLL).


Failed to load the native TensorFlow runtime.
See https://www.tensorflow.org/install/errors for some common causes and solutions.
If you need help, create an issue at https://github.com/tensorflow/tensorflow/issues and include the entire stack trace above this error message.

2024-08-12 09:47:12,530 - Executing Training the Model...
2024-08-12 09:47:12,530 - Executing Making Predictions...
2024-08-12 09:47:12,530 - Executing Continuous Learning...
2024-08-12 09:47:16,733 - Error executing Training the Model: Traceback (most recent call last):
  File "C:\Users\proalafalda\AppData\Local\Programs\Python\Python312\Lib\site-packages\tensorflow\python\pywrap_tensorflow.py", line 70, in <module>
    from tensorflow.python._pywrap_tensorflow_internal import *
ImportError: DLL load failed while importing _pywrap_tensorflow_internal: Error en una rutina de inicialización de biblioteca de vínculos dinámicos (DLL).

During handling of the above exception, another exception occurred:

Traceback (most recent call last):
  File "C:\Users\proalafalda\Documents\GHUBJordan\ProBestoJarvisAI\TEST\JarvisPhone\training\train.py", line 2, in <module>
    import tensorflow as tf
  File "C:\Users\proalafalda\AppData\Local\Programs\Python\Python312\Lib\site-packages\tensorflow\__init__.py", line 38, in <module>
    from tensorflow.python import pywrap_tensorflow as _pywrap_tensorflow  # pylint: disable=unused-import
    ^^^^^^^^^^^^^^^^^^^^^^^^^^^^^^^^^^^^^^^^^^^^^^^^^^^^^^^^^^^^^^^^^^^^^
  File "C:\Users\proalafalda\AppData\Local\Programs\Python\Python312\Lib\site-packages\tensorflow\python\pywrap_tensorflow.py", line 85, in <module>
    raise ImportError(
ImportError: Traceback (most recent call last):
  File "C:\Users\proalafalda\AppData\Local\Programs\Python\Python312\Lib\site-packages\tensorflow\python\pywrap_tensorflow.py", line 70, in <module>
    from tensorflow.python._pywrap_tensorflow_internal import *
ImportError: DLL load failed while importing _pywrap_tensorflow_internal: Error en una rutina de inicialización de biblioteca de vínculos dinámicos (DLL).


Failed to load the native TensorFlow runtime.
See https://www.tensorflow.org/install/errors for some common causes and solutions.
If you need help, create an issue at https://github.com/tensorflow/tensorflow/issues and include the entire stack trace above this error message.

2024-08-12 09:47:16,733 - Error executing Making Predictions: Traceback (most recent call last):
  File "C:\Users\proalafalda\AppData\Local\Programs\Python\Python312\Lib\site-packages\tensorflow\python\pywrap_tensorflow.py", line 70, in <module>
    from tensorflow.python._pywrap_tensorflow_internal import *
ImportError: DLL load failed while importing _pywrap_tensorflow_internal: Error en una rutina de inicialización de biblioteca de vínculos dinámicos (DLL).

During handling of the above exception, another exception occurred:

Traceback (most recent call last):
  File "C:\Users\proalafalda\Documents\GHUBJordan\ProBestoJarvisAI\TEST\JarvisPhone\predictions.py", line 3, in <module>
    import tensorflow as tf
  File "C:\Users\proalafalda\AppData\Local\Programs\Python\Python312\Lib\site-packages\tensorflow\__init__.py", line 38, in <module>
    from tensorflow.python import pywrap_tensorflow as _pywrap_tensorflow  # pylint: disable=unused-import
    ^^^^^^^^^^^^^^^^^^^^^^^^^^^^^^^^^^^^^^^^^^^^^^^^^^^^^^^^^^^^^^^^^^^^^
  File "C:\Users\proalafalda\AppData\Local\Programs\Python\Python312\Lib\site-packages\tensorflow\python\pywrap_tensorflow.py", line 85, in <module>
    raise ImportError(
ImportError: Traceback (most recent call last):
  File "C:\Users\proalafalda\AppData\Local\Programs\Python\Python312\Lib\site-packages\tensorflow\python\pywrap_tensorflow.py", line 70, in <module>
    from tensorflow.python._pywrap_tensorflow_internal import *
ImportError: DLL load failed while importing _pywrap_tensorflow_internal: Error en una rutina de inicialización de biblioteca de vínculos dinámicos (DLL).


Failed to load the native TensorFlow runtime.
See https://www.tensorflow.org/install/errors for some common causes and solutions.
If you need help, create an issue at https://github.com/tensorflow/tensorflow/issues and include the entire stack trace above this error message.

2024-08-12 09:53:00,613 - Executing Training the Model...
2024-08-12 09:53:00,613 - Executing Making Predictions...
2024-08-12 09:53:00,613 - Executing Continuous Learning...
2024-08-12 09:53:04,898 - Error executing Training the Model: Traceback (most recent call last):
  File "C:\Users\proalafalda\AppData\Local\Programs\Python\Python312\Lib\site-packages\tensorflow\python\pywrap_tensorflow.py", line 70, in <module>
    from tensorflow.python._pywrap_tensorflow_internal import *
ImportError: DLL load failed while importing _pywrap_tensorflow_internal: Error en una rutina de inicialización de biblioteca de vínculos dinámicos (DLL).

During handling of the above exception, another exception occurred:

Traceback (most recent call last):
  File "C:\Users\proalafalda\Documents\GHUBJordan\ProBestoJarvisAI\TEST\JarvisPhone\training\train.py", line 2, in <module>
    import tensorflow as tf
  File "C:\Users\proalafalda\AppData\Local\Programs\Python\Python312\Lib\site-packages\tensorflow\__init__.py", line 38, in <module>
    from tensorflow.python import pywrap_tensorflow as _pywrap_tensorflow  # pylint: disable=unused-import
    ^^^^^^^^^^^^^^^^^^^^^^^^^^^^^^^^^^^^^^^^^^^^^^^^^^^^^^^^^^^^^^^^^^^^^
  File "C:\Users\proalafalda\AppData\Local\Programs\Python\Python312\Lib\site-packages\tensorflow\python\pywrap_tensorflow.py", line 85, in <module>
    raise ImportError(
ImportError: Traceback (most recent call last):
  File "C:\Users\proalafalda\AppData\Local\Programs\Python\Python312\Lib\site-packages\tensorflow\python\pywrap_tensorflow.py", line 70, in <module>
    from tensorflow.python._pywrap_tensorflow_internal import *
ImportError: DLL load failed while importing _pywrap_tensorflow_internal: Error en una rutina de inicialización de biblioteca de vínculos dinámicos (DLL).


Failed to load the native TensorFlow runtime.
See https://www.tensorflow.org/install/errors for some common causes and solutions.
If you need help, create an issue at https://github.com/tensorflow/tensorflow/issues and include the entire stack trace above this error message.

2024-08-12 09:53:05,102 - Error executing Making Predictions: Traceback (most recent call last):
  File "C:\Users\proalafalda\AppData\Local\Programs\Python\Python312\Lib\site-packages\tensorflow\python\pywrap_tensorflow.py", line 70, in <module>
    from tensorflow.python._pywrap_tensorflow_internal import *
ImportError: DLL load failed while importing _pywrap_tensorflow_internal: Error en una rutina de inicialización de biblioteca de vínculos dinámicos (DLL).

During handling of the above exception, another exception occurred:

Traceback (most recent call last):
  File "C:\Users\proalafalda\Documents\GHUBJordan\ProBestoJarvisAI\TEST\JarvisPhone\predictions.py", line 3, in <module>
    import tensorflow as tf
  File "C:\Users\proalafalda\AppData\Local\Programs\Python\Python312\Lib\site-packages\tensorflow\__init__.py", line 38, in <module>
    from tensorflow.python import pywrap_tensorflow as _pywrap_tensorflow  # pylint: disable=unused-import
    ^^^^^^^^^^^^^^^^^^^^^^^^^^^^^^^^^^^^^^^^^^^^^^^^^^^^^^^^^^^^^^^^^^^^^
  File "C:\Users\proalafalda\AppData\Local\Programs\Python\Python312\Lib\site-packages\tensorflow\python\pywrap_tensorflow.py", line 85, in <module>
    raise ImportError(
ImportError: Traceback (most recent call last):
  File "C:\Users\proalafalda\AppData\Local\Programs\Python\Python312\Lib\site-packages\tensorflow\python\pywrap_tensorflow.py", line 70, in <module>
    from tensorflow.python._pywrap_tensorflow_internal import *
ImportError: DLL load failed while importing _pywrap_tensorflow_internal: Error en una rutina de inicialización de biblioteca de vínculos dinámicos (DLL).


Failed to load the native TensorFlow runtime.
See https://www.tensorflow.org/install/errors for some common causes and solutions.
If you need help, create an issue at https://github.com/tensorflow/tensorflow/issues and include the entire stack trace above this error message.

